<mujoco model="X5liteaa0">
  <compiler angle="radian"/>

  <asset>
    <mesh name="base_link" content_type="model/stl" file="base_link.STL"/>
    <mesh name="link1" content_type="model/stl" file="link1.STL"/>
    <mesh name="link2" content_type="model/stl" file="link2.STL"/>
    <mesh name="link3" content_type="model/stl" file="link3.STL"/>
    <mesh name="link4" content_type="model/stl" file="link4.STL"/>
    <mesh name="link5" content_type="model/stl" file="link5.STL"/>
    <mesh name="link6" content_type="model/stl" file="link6.STL"/>
  </asset>

  <worldbody>
    <geom type="mesh" rgba="0.89804 0.91765 0.92941 1" mesh="base_link"/>
    <body name="link1" pos="0 0 0.0565">
      <inertial pos="0.005056 -0.0078534 0.020887" quat="0.632157 0.714526 -0.263733 0.142391" mass="0.09728" diaginertia="0.000118945 9.40205e-05 4.70346e-05"/>
      <joint name="joint1" pos="0 0 0" axis="0 0 1" range="-10 10" actuatorfrcrange="-100 100"/>
      <geom type="mesh" rgba="0.56471 0.56471 0.56471 1" mesh="link1"/>
      <body name="link2" pos="0.02 0 0.047">
        <inertial pos="-0.12983 -0.00073729 -1.2236e-05" quat="0.501998 0.500475 0.499214 0.498305" mass="1.1477" diaginertia="0.0167604 0.01674 0.000609598"/>
        <joint name="joint2" pos="0 0 0" axis="0 1 0" range="-10 10" actuatorfrcrange="-100 100"/>
        <geom type="mesh" rgba="0.69804 0.69804 0.69804 1" mesh="link2"/>
        <body name="link3" pos="-0.264 0 0" quat="-3.67321e-06 1 0 0">
          <inertial pos="0.15404 5.5044e-07 -0.054689" quat="0.423803 0.54716 0.3939 0.604855" mass="0.74116" diaginertia="0.00748443 0.00736241 0.000643155"/>
          <joint name="joint3" pos="0 0 0" axis="0 1 0" range="-10 10" actuatorfrcrange="-100 100"/>
          <geom type="mesh" rgba="0.89804 0.91765 0.92941 1" mesh="link3"/>
          <body name="link4" pos="0.245 0 -0.06">
            <inertial pos="0.040231 0.0039307 -0.035335" quat="0.911288 -0.0751532 0.308689 -0.261949" mass="0.11714" diaginertia="0.000275643 0.00021286 7.14977e-05"/>
            <joint name="joint4" pos="0 0 0" axis="0 1 0" range="-10 10" actuatorfrcrange="-100 100"/>
            <geom type="mesh" rgba="0.56471 0.56471 0.56471 1" mesh="link4"/>
            <body name="link5" pos="0.06775 -5e-05 -0.0865">
              <inertial pos="0.0036004 -1.5445e-05 0.055255" quat="0.998247 0 -0.0591776 0" mass="0.6353" diaginertia="0.000848329 0.00082 0.000251671"/>
              <joint name="joint5" pos="0 0 0" axis="0 0 1" range="-10 10" actuatorfrcrange="-100 100"/>
              <geom type="mesh" rgba="0.69804 0.69804 0.69804 1" mesh="link5"/>
              <body name="link6" pos="0.02895 0 0.0865" quat="-3.67321e-06 1 0 0">
                <inertial pos="0.050676 -4.9137e-05 5.123e-05" quat="0 0.707107 0 0.707107" mass="0.281" diaginertia="0.00078 0.00051 0.00046"/>
                <joint name="joint6" pos="0 0 0" axis="1 0 0" range="-10 10" actuatorfrcrange="-100 100"/>
                <geom type="mesh" rgba="0.79216 0.81961 0.93333 1" mesh="link6"/>
              </body>
            </body>
          </body>
        </body>
      </body>
    </body>
  </worldbody>
</mujoco>
